<?xml version="1.0"?>
<robot name="devastator" xmlns:xacro="http://www.ros.org/wiki/xacro">

  <xacro:include filename="$(find devastator)/devastator_description/urdf/devastator_full.gazebo.xacro" />
  <!--xacro:include filename="$(find mybot_description)/urdf/materials.xacro" /-->
  <xacro:include filename="$(find mybot_description)/urdf/macros.xacro" />


<!--ROBOT BASE-->
<link name="base_link">
	<visual>
		<origin rpy="0 0 0" xyz="0 0 0"/>
		<geometry>
			<mesh filename="package://devastator/devastator_description/meshes/base/base_full.dae"/>
		</geometry>
    </visual>

	<collision>
		<origin xyz="0.0 0.0 0.0" rpy="0 0 0"/>
		<geometry>
			<box size="0.20576 0.12131 0.07112"/>
		</geometry>
	</collision>

	<inertial>
		<origin xyz="0 0 0" rpy="0 0 0"/>
		<mass value="5.40e-01"/>

	<inertia ixx="2.2124416e-03" ixy="-1.2294101e-05" ixz="3.4938785e-05"
               iyy="2.1193702e-03" iyz="-5.0120904e-06"
               izz="2.0064271e-03" />
	</inertial>
</link>

<!-- RIGHT WHEELS -->
<link name="wheel_one_right">

	<visual>
		<origin rpy="0 0 0" xyz="0 0 0"/>
		<geometry>
			<mesh filename="package://devastator/devastator_description/meshes/wheels/wheel_basic.dae"/>
		</geometry>
	</visual>


	<collision>
		<origin xyz="0 0 0" rpy="1.57 0 0"/>
		<geometry>
			<cylinder length="0.025" radius="0.020" />
		</geometry>
	</collision>

	<inertial>

		<origin xyz="0 0 0" rpy="0 0 0"/>
		<mass value="1.2e-02"/>


		<inertia ixx="1.1175580e-05" ixy="-4.2369783e-11" ixz="-5.9381719e-09"
				iyy="1.1192413e-05" iyz="-1.4400107e-11"
               izz="2.0712558e-05" />
	</inertial>
</link>

<joint name="wheel_one_right" type="continuous">
	<parent link="base_link"/>
	<child link="wheel_one_right"/>
	<origin xyz="0.10538 -0.095 0.008" rpy="0 0 0"/>
	<axis xyz="0 1 0"/>
</joint>

<link name="wheel_two_right">
	<visual>
		<origin rpy="0 0 0" xyz="0 0 0"/>
		<geometry>
			<mesh filename="package://devastator/devastator_description/meshes/wheels/wheel_basic.dae"/>
		</geometry>
	</visual>

	<collision>
		<origin xyz="0 0 0" rpy="1.57 0 0"/>
		<geometry>
			<cylinder length="0.025" radius="0.020" />
		</geometry>
	</collision>

	<inertial>

		<origin xyz="0 0 0" rpy="0 0 0"/>
		<mass value="1.2e-02"/>


		<inertia ixx="3.0153996560e-03" ixy="0.0" ixz="1.7522996572e-11"
					iyy="4.0932945308e-03" iyz="0.0"
					izz="3.0153987822e-03"/>
	</inertial>

</link>

<joint name="wheel_two_right" type="continuous">
	<parent link="base_link"/>
	<child link="wheel_two_right"/>
	<origin xyz="0.07363 -0.095 -0.025" rpy="0 0 0"/>
	<limit effort="100" velocity="100"/>
    <joint_properties damping="0.0" friction="0.0"/>
	<axis xyz="0 1 0"/>
</joint>

<link name="wheel_three_right">
	<visual>
		<origin rpy="0 0 0" xyz="0 0 0"/>
		<geometry>
			<mesh filename="package://devastator/devastator_description/meshes/wheels/wheel_basic.dae"/>
		</geometry>
	</visual>

	<collision>
		<origin xyz="0 0 0" rpy="1.57 0 0"/>
		<geometry>
			<cylinder length="0.025" radius="0.020" />
		</geometry>
	</collision>

	<inertial>

		<origin xyz="0 0 0" rpy="0 0 0"/>
		<mass value="1.2e-02"/>


		<inertia ixx="1.1175580e-05" ixy="-4.2369783e-11" ixz="-5.9381719e-09"
				iyy="1.1192413e-05" iyz="-1.4400107e-11"
               izz="2.0712558e-05" />
	</inertial>
</link>

<joint name="wheel_three_right" type="continuous">
	<parent link="base_link"/>
	<child link="wheel_three_right"/>
	<origin xyz="0.00765 -0.095 -0.025" rpy="0 0 0"/>
	<limit effort="100" velocity="100"/>
    <joint_properties damping="0.0" friction="0.0"/>
	<axis xyz="0 1 0"/>
</joint>

<link name="wheel_four_right">
	<visual>
		<origin rpy="0 0 0" xyz="0 0 0"/>
		<geometry>
			<mesh filename="package://devastator/devastator_description/meshes/wheels/wheel_basic.dae"/>
		</geometry>
	</visual>

	<collision>
		<origin xyz="0 0 0" rpy="1.57 0 0"/>
		<geometry>
			<cylinder length="0.025" radius="0.020" />
		</geometry>
	</collision>

	<inertial>

		<origin xyz="0 0 0" rpy="0 0 0"/>
		<mass value="1.2e-02"/>


		<inertia ixx="1.1175580e-05" ixy="-4.2369783e-11" ixz="-5.9381719e-09"
				iyy="1.1192413e-05" iyz="-1.4400107e-11"
               izz="2.0712558e-05" />
	</inertial>
</link>

<joint name="wheel_four_right" type="continuous">
	<parent link="base_link"/>
	<child link="wheel_four_right"/>
	<origin xyz="-0.05464 -0.095 -0.025" rpy="0 0 0"/>
	<limit effort="100" velocity="100"/>
    <joint_properties damping="0.0" friction="0.0"/>
	<axis xyz="0 1 0"/>
</joint>

<!--LEFT WHEELS-->
<link name="wheel_one_left">
	<visual>
		<origin rpy="0 0 3.14159" xyz="0 0 0"/>
		<geometry>
			<mesh filename="package://devastator/devastator_description/meshes/wheels/wheel_basic.dae"/>
		</geometry>
	</visual>

	<collision>
		<origin xyz="0 0 0" rpy="1.57 0 0"/>
		<geometry>
			<cylinder length="0.025" radius="0.020" />
		</geometry>
	</collision>

	<inertial>

		<origin xyz="0 0 0" rpy="0 0 0"/>
		<mass value="1.2e-02"/>


		<inertia ixx="1.1175580e-05" ixy="-4.2369783e-11" ixz="-5.9381719e-09"
				iyy="1.1192413e-05" iyz="-1.4400107e-11"
               izz="2.0712558e-05" />
	</inertial>

</link>

<joint name="wheel_one_left" type="continuous">
	<parent link="base_link"/>
	<child link="wheel_one_left"/>
	<origin xyz="0.10538 0.095  0.008" rpy="0 0 0"/>
	<limit effort="100" velocity="100"/>
    <joint_properties damping="0.0" friction="0.0"/>
	<axis xyz="0 1 0"/>
</joint>

<link name="wheel_two_left">
	<visual>
		<origin rpy="0 0 3.14159" xyz="0 0 0"/>
		<geometry>
			<mesh filename="package://devastator/devastator_description/meshes/wheels/wheel_basic.dae"/>
		</geometry>
	</visual>

	<collision>
		<origin xyz="0 0 0" rpy="1.57 0 0"/>
		<geometry>
			<cylinder length="0.025" radius="0.020" />
		</geometry>
	</collision>

	<inertial>

		<origin xyz="0 0 0" rpy="0 0 0"/>
		<mass value="1.2e-02"/>


		<inertia ixx="1.1175580e-05" ixy="-4.2369783e-11" ixz="-5.9381719e-09"
				iyy="1.1192413e-05" iyz="-1.4400107e-11"
               izz="2.0712558e-05" />
	</inertial>
</link>

<joint name="wheel_two_left" type="continuous">
	<parent link="base_link"/>
	<child link="wheel_two_left"/>
	<origin xyz="0.07363 0.095  -0.025" rpy="0 0 0"/>
	<limit effort="100" velocity="100"/>
    <joint_properties damping="0.0" friction="0.0"/>
	<axis xyz="0 1 0"/>
</joint>

<link name="wheel_three_left">
	<visual>
		<origin rpy="0 0 3.14159" xyz="0 0 0"/>
		<geometry>
			<mesh filename="package://devastator/devastator_description/meshes/wheels/wheel_basic.dae"/>
		</geometry>
	</visual>

	<collision>
		<origin xyz="0 0 0" rpy="1.57 0 0"/>
		<geometry>
			<cylinder length="0.025" radius="0.020" />
		</geometry>
	</collision>

	<inertial>

		<origin xyz="0 0 0" rpy="0 0 0"/>
		<mass value="1.2e-02"/>


		<inertia ixx="1.1175580e-05" ixy="-4.2369783e-11" ixz="-5.9381719e-09"
				iyy="1.1192413e-05" iyz="-1.4400107e-11"
               izz="2.0712558e-05" />
	</inertial>
</link>

<joint name="wheel_three_left" type="continuous">
	<parent link="base_link"/>
	<child link="wheel_three_left"/>
	<origin xyz="0.00765 0.095  -0.025" rpy="0 0 0"/>
	<limit effort="100" velocity="100"/>
    <joint_properties damping="0.0" friction="0.0"/>
	<axis xyz="0 1 0"/>
</joint>

<link name="wheel_four_left">
	<visual>
		<origin rpy="0 0 3.14159" xyz="0 0 0"/>
		<geometry>
			<mesh filename="package://devastator/devastator_description/meshes/wheels/wheel_basic.dae"/>
		</geometry>
	</visual>

	<collision>
		<origin xyz="0 0 0" rpy="1.57 0 0"/>
		<geometry>
			<cylinder length="0.025" radius="0.020" />
		</geometry>
	</collision>

	<inertial>

		<origin xyz="0 0 0" rpy="0 0 0"/>
		<mass value="1.2e-02"/>


		<inertia ixx="1.1175580e-05" ixy="-4.2369783e-11" ixz="-5.9381719e-09"
				iyy="1.1192413e-05" iyz="-1.4400107e-11"
               izz="2.0712558e-05" />
	</inertial>

</link>

<joint name="wheel_four_left" type="continuous">
	<parent link="base_link"/>
	<child link="wheel_four_left"/>
	<origin xyz="-0.05464 0.095 -0.025" rpy="0 0 0"/>
	<limit effort="100" velocity="100"/>
    <joint_properties damping="0.0" friction="0.0"/>
	<axis xyz="0 1 0"/>
</joint>


<link name="tracked_wheel_right">
	<visual>
		<origin rpy="0 0 0" xyz="0 0 0"/>
		<geometry>
			<mesh filename="package://devastator/devastator_description/meshes/wheels/wheel_track.dae"/>
		</geometry>
	</visual>

	<collision>
		<origin xyz="0 0 0" rpy="0 0 0"/>
		<geometry>
			<cylinder length="0.025" radius="0.023" />
		</geometry>
	</collision>

	<inertial>

		<origin xyz="0 0 0" rpy="0 0 0"/>
		<mass value="9.0e-02"/>


		<inertia ixx="1.1175580e-05" ixy="-4.2369783e-11" ixz="-5.9381719e-09"
				iyy="1.1192413e-05" iyz="-1.4400107e-11"
               izz="2.0712558e-05" />
	</inertial>
</link>

<joint name="tracked_wheel_right" type="continuous">
	<parent link="base_link"/>
	<child link="tracked_wheel_right"/>
	<origin xyz="-0.0027 0.073 0.0375" rpy="-1.57 0 -3.14"/>
	<limit effort="100" velocity="100"/>
    <joint_properties damping="0.0" friction="0.0"/>
	<axis xyz="0 0 1"/>
</joint>

<link name="tracked_wheel_left">
	<visual>
		<origin rpy="0 0 0" xyz="0 0 0"/>
		<geometry>
			<mesh filename="package://devastator/devastator_description/meshes/wheels/wheel_track.dae"/>
		</geometry>
	</visual>

	<collision>
		<origin xyz="0 0 0" rpy="0 0 0"/>
		<geometry>
			<cylinder length="0.025" radius="0.023" />
		</geometry>
	</collision>

	<inertial>

		<origin xyz="0 0 0" rpy="0 0 0"/>
		<mass value="9.0e-02"/>


		<inertia ixx="1.1175580e-05" ixy="-4.2369783e-11" ixz="-5.9381719e-09"
				iyy="1.1192413e-05" iyz="-1.4400107e-11"
               izz="2.0712558e-05" />
	</inertial>
</link>

<joint name="tracked_wheel_left" type="continuous">
	<parent link="base_link"/>
	<child link="tracked_wheel_left"/>
	<origin xyz="-0.0027 -0.073  0.0375" rpy="-1.57 0 0"/>
	<limit effort="100" velocity="100"/>
    <joint_properties damping="0.0" friction="0.0"/>
	<axis xyz="0 0 1"/>
</joint>


<!--SENSORS/ACCESSORIES-->
<link name="camera_pan">
  <collision>
    <origin xyz="0 0 0" rpy="0 0 0"/>
    <geometry>
    <!-- box size ="width lengtht height"-->
      <box size="0.01 0.025 0.03"/>
    </geometry>
  </collision>

  <visual>
    <origin xyz="0 0 0" rpy="0 0 0"/>
    <geometry>
      <mesh filename="package://devastator/devastator_description/meshes/base/camera_pan.dae"/>
    </geometry>
  </visual>

  <!--inertial>
  <mass value="${cameraMass}" />
  <origin xyz="0 0 0" rpy="0 0 0"/>
  <box_inertia m="${cameraMass}" x="${cameraSize}" y="${cameraSize}" z="${cameraSize}" />
  <inertia ixx="1.0e-6" ixy="0.0" ixz="0.0"
  iyy="1.0e-6" iyz="0.0" izz="1.0e-6" />
  </inertial-->
</link>

<joint name="camera_pan_joint" type="revolute">
  <parent link="base_link"/>
  <child link="camera_pan"/>
  <origin xyz="0.0545 0  0.1125" rpy="0 0 0"/>
  <limit effort="1000.0" lower="0.0" upper="6.2831" velocity="0.5"/>
  <axis xyz="0 0 1"/>
</joint>


<link name="camera">
  <collision>
    <origin xyz="0 0 0" rpy="0 0 0"/>
    <geometry>
      <box size="0.005 0.01 0.01"/>
    </geometry>
  </collision>

  <visual>
    <origin xyz="0 0 0" rpy="0 0 0"/>
    <geometry>
      <mesh filename="package://devastator/devastator_description/meshes/sensors/camera.dae"/>
    </geometry>
  </visual>

  <inertial>
    <mass value="0.25" />
    <origin xyz="0 0 0" rpy="0 0 0"/>
    <box_inertia m="0.25" x="0.015" y="0.015" z="0.02" />
    <inertia ixx="1.0e-6" ixy="0.0" ixz="0.0"
    iyy="1.0e-6" iyz="0.0" izz="1.0e-6" />
  </inertial>
</link>
<joint name="camera_joint" type="fixed">
  <axis xyz="0 1 0" />
  <origin xyz="0.00625 0 0.01" rpy="0 0 0"/>
  <parent link="camera_pan"/>
  <child link="camera"/>
</joint>


<link name="dIR_BL">
  <collision>
    <axis xyz="0 0 0" />
    <origin xyz="0.0085 0 0" rpy="0 1.57 0"/>
  <geometry>
    <cylinder  length="0.017" radius="0.0045" />
  </geometry>
  </collision>

  <visual>
  <origin xyz="0 0 0" rpy="0 0 0"/>
  <geometry>
    <mesh filename="package://devastator/devastator_description/meshes/sensors/digital_ir.dae"/>
  </geometry>
  </visual>

  <inertial>
    <mass value="0.25" />
    <origin xyz="0 0 0" rpy="0 0 0"/>
    <box_inertia m="0.25" x="0.015" y="0.015" z="0.02" />
    <inertia ixx="1.0e-6" ixy="0.0" ixz="0.0"
    iyy="1.0e-6" iyz="0.0" izz="1.0e-6" />
  </inertial>
</link>

<joint name="dIR_BL_joint" type="fixed">
  <axis xyz="0 1 0" />
  <origin xyz="-0.11676 0.05761 0.06139" rpy="0 3.1416 0"/>
  <parent link="base_link"/>
  <child link="dIR_BL"/>
</joint>

<link name="dIR_BR">
  <collision>
    <axis xyz="0 1 0" />
    <origin xyz="0.0085 0 0" rpy="0 1.57 0"/>

    <geometry>
      <cylinder radius="0.0045" length="0.017" />
    </geometry>
  </collision>

  <visual>
    <origin xyz="0 0 0" rpy="0 0 0"/>
    <geometry>
      <mesh filename="package://devastator/devastator_description/meshes/sensors/digital_ir.dae"/>
    </geometry>
  </visual>

  <inertial>
    <mass value="0.25" />
    <origin xyz="0 0 0" rpy="0 0 0"/>
    <box_inertia m="0.25" x="0.015" y="0.015" z="0.02" />
    <inertia ixx="1.0e-6" ixy="0.0" ixz="0.0"
    iyy="1.0e-6" iyz="0.0" izz="1.0e-6" />
  </inertial>
</link>

<joint name="dIR_BR_joint" type="fixed">
  <axis xyz="0 1 0" />
  <origin xyz="-0.11676 -0.05761 0.06139" rpy="0 3.1416 0"/>
  <parent link="base_link"/>
  <child link="dIR_BR"/>
</joint>


<link name="aIR_FR">
  <collision>
    <origin xyz="0 0 -0.00709" rpy="0 0 0"/>
    <geometry>
      <box size="0.01418 0.04839 0.013"/>
    </geometry>
  </collision>

  <visual>
    <origin xyz="0 0 0" rpy="0 0 0"/>
    <geometry>
      <mesh filename="package://devastator/devastator_description/meshes/sensors/analog_ir.dae"/>
    </geometry>
  </visual>

  <inertial>
    <mass value="0.25" />
    <origin xyz="0 0 0" rpy="0 0 0"/>
    <box_inertia m="0.25" x="0.015" y="0.015" z="0.02" />
    <inertia ixx="1.0e-6" ixy="0.0" ixz="0.0"
    iyy="1.0e-6" iyz="0.0" izz="1.0e-6" />
  </inertial>
</link>

<joint name="aIR_FR_joint" type="revolute">
  <axis xyz="0 0 1" />
  <origin xyz="0.09648 -0.06266 0.06481" rpy="0 0 -0.7217"/>
  <limit effort="1000.0" lower="0.0" upper="1.2217" velocity="0.5"/>
  <parent link="base_link"/>
  <child link="aIR_FR"/>
</joint>

<link name="aIR_FL">
  <collision>
    <origin xyz="0 0 -0.00709" rpy="0 0 0"/>
    <geometry>
      <box size="0.01418 0.04839 0.013"/>
    </geometry>
  </collision>

  <visual>
    <origin xyz="0 0 0" rpy="0 0 0"/>
    <geometry>
      <mesh filename="package://devastator/devastator_description/meshes/sensors/analog_ir.dae"/>
    </geometry>
  </visual>

  <inertial>
    <mass value="0.25" />
    <origin xyz="0 0 0" rpy="0 0 0"/>
    <box_inertia m="0.25" x="0.015" y="0.015" z="0.02" />
    <inertia ixx="1.0e-6" ixy="0.0" ixz="0.0"
    iyy="1.0e-6" iyz="0.0" izz="1.0e-6" />
  </inertial>
</link>

<joint name="aIR_FL_joint" type="revolute">
  <axis xyz="0 0 1" />
  <origin xyz="0.09648 0.06266 0.06481" rpy="0 0 0.7217"/>
  <limit effort="1000.0" lower="-1.2217" upper="0.0" velocity="0.5"/>
  <parent link="base_link"/>
  <child link="aIR_FL"/>
</joint>

<link name="sonic_FD">
  <collision>
    <origin xyz="0.00725 0 0" rpy="0 0 0"/>
    <geometry>
      <box size="0.0145 0.04572 0.02"/>
    </geometry>
  </collision>

  <visual>
    <origin xyz="0 0 0" rpy="0 0 0"/>
    <geometry>
      <mesh filename="package://devastator/devastator_description/meshes/sensors/ultrasonic.dae"/>
    </geometry>
  </visual>

  <inertial>
    <mass value="0.25" />
    <origin xyz="0 0 0" rpy="0 0 0"/>
    <box_inertia m="0.25" x="0.015" y="0.015" z="0.02" />
    <inertia ixx="1.0e-6" ixy="0.0" ixz="0.0"
    iyy="1.0e-6" iyz="0.0" izz="1.0e-6" />
  </inertial>
</link>

<joint name="sonic_FD" type="fixed">
  <axis xyz="0 0 1" />
  <origin xyz="0.0992 0 0.03481" rpy="0 0 0"/>
  <parent link="base_link"/>
  <child link="sonic_FD"/>
</joint>

<link name="sonic_FF">
  <collision>
    <origin xyz="0.00725 0 0" rpy="0 0 0"/>
    <geometry>
      <box size="0.0145 0.04572 0.02"/>
    </geometry>
  </collision>

  <visual>
    <origin xyz="0 0 0" rpy="0 0 0"/>
    <geometry>
      <mesh filename="package://devastator/devastator_description/meshes/sensors/ultrasonic.dae"/>
    </geometry>
  </visual>

  <inertial>
    <mass value="0.25" />
    <origin xyz="0 0 0" rpy="0 0 0"/>
    <box_inertia m="0.25" x="0.015" y="0.015" z="0.02" />
    <inertia ixx="1.0e-6" ixy="0.0" ixz="0.0"
    iyy="1.0e-6" iyz="0.0" izz="1.0e-6" />
  </inertial>
</link>

<joint name="sonic_FF" type="fixed">
  <axis xyz="0 1 0" />
  <origin xyz="0.07229 0.02739 0.10304" rpy="0 0.20944 0"/>
  <parent link="base_link"/>
  <child link="sonic_FF"/>
</joint>

<link name="dIR_FF">
  <collision>
    <axis xyz="0 1 0" />
    <origin xyz="0.0085 0 0" rpy="0 -1.57 0"/>
    <geometry>
      <cylinder length="0.017" radius="0.0045"/>
    </geometry>
  </collision>

  <visual>
    <origin xyz="0 0 0" rpy="0 0 0"/>
    <geometry>
      <mesh filename="package://devastator/devastator_description/meshes/sensors/digital_ir.dae"/>
    </geometry>
  </visual>

  <inertial>
    <mass value="0.25" />
    <origin xyz="0 0 0" rpy="0 0 0"/>
    <box_inertia m="0.25" x="0.015" y="0.015" z="0.02" />
    <inertia ixx="1.0e-6" ixy="0.0" ixz="0.0"
    iyy="1.0e-6" iyz="0.0" izz="1.0e-6" />
  </inertial>
</link>

<joint name="dIR_FF" type="fixed">
  <axis xyz="0 1 0" />
  <origin xyz="0.07229 0 0.10304" rpy="0 0.20944 0"/>
  <parent link="base_link"/>
  <child link="dIR_FF"/>
</joint>
<!--link name="hokuyo">
    <collision>
      <origin xyz="0 0 0" rpy="0 0 0"/>
      <geometry>
		<box size="0.04 0.04 0.04"/>
      </geometry>
    </collision>

    <visual>
      <origin xyz="0 0 0" rpy="0 0 0"/>
      <geometry>
        <mesh filename="package://devastator/devastator_description/meshes/sensors/hokuyo.dae"/>
      </geometry>

    </visual>

    <inertial>
      <mass value="${cameraMass}" />
      <origin xyz="0 0 0" rpy="0 0 0"/>
      <box_inertia m="${cameraMass}" x="${cameraSize}" y="${cameraSize}" z="${cameraSize}" />
      <inertia ixx="1.0e-6" ixy="0.0" ixz="0.0"
	  iyy="1.0e-6" iyz="0.0" izz="1.0e-6" />
    </inertial>
</link>

  <joint name="hokuyo_joint" type="fixed">
    <axis xyz="0 1 0" />
	<origin xyz="0.06 0 0.09" rpy="0 0 0"/>

    <parent link="base_link"/>
    <child link="hokuyo"/>
  </joint>


<link name="belt">
	<visual>
		<origin rpy="0 0 0" xyz="0 0 0"/>
		<geometry>
			<mesh filename="package://devastator/devastator_description/meshes/wheels/belt2.dae"/>
		</geometry>
	</visual>

	<collision>
		<origin xyz="0 0 0" rpy="0 0 0"/>
		<geometry>
			<cylinder length="0.018" radius="0.033"/>
		</geometry>
	</collision>

	<inertial>
	<mass value= "0.212"/>

  <Inertia matrix>
		<inertia ixx="1.0" ixy=" 0" ixz="0.0"
		iyy="1.0 " iyz="0.0"
		izz="1.0 " />
	</inertial>
</link>

<joint name="belt" type="continuous">
	<parent link="base_link"/>
	<child link="belt"/>
	<origin xyz="0 0 0" rpy="0 0 0"/>
	<axis xyz="0 0 1"/>
</joint -->

</robot>
